Workbook

Sheet Gastos proyecto
A1: 6744 SERVICIO POR LIMPIEZA Y APLICACIÓN DE SILICÓN DURETAN EN ALUMINIO Y CRISTAL, MURO Y ALUMINIO DE LOS VENTANALES DE LA PARROQUIA (EXTERIOR) IGLESIA SAN JUAN DE LOS LAGOS
A3: Usuario: | B3: JAVIER LOZANO | F3: Cotización: | G3: 6744
A4: Planta: | B4: IGLESIA SAN JUAN DE LOS LAGOS | F4: Hoja de levantamiento: | G4: 3434
A5: Proyecto: | B5: =A1 -> 6744 SERVICIO POR LIMPIEZA Y APLICACIÓN DE SILICÓN DURETAN EN ALUMINIO Y CRISTAL, MURO Y ALUMINIO DE LOS VENTANALES DE LA PARROQUIA (EXTERIOR) IGLESIA SAN JUAN DE LOS LAGOS | F5: Dias de trabajo: | G5: 5
F6: Personal: | G6: 6
A7: Vendedor: | B7: JUAN GAYTAN | C7: Fecha de emision: | D7: 46260 | F7: Hoja de entrega:
A9: Gasto total plan | F9: Gasto total Real
A10: Costo sin Iva | C10: 130800 | D10: 130800 | E10: AUTORIZA RODOLFO | F10: Costo sin Iva | G10: =C10 -> 130800
A11: ISR | C11: 1000 | F11: ISR | G11: 1000 | H11: 4100
A12: Gasto total planeado | C12: =C35 -> 31939 | F12: Gasto total real | G12: =+D35 -> 31939 | H12: =H11*5*6 -> 123000 | I12: 6 TEC EN ALT. POR 5 DIAS
A13: Impuestos 10% | C13: =C12*0.1 -> 3193.9 | F13: Impuestos 10% | G13: =G12*0.1 -> 3193.9 | H13: 109846.24 | I13: COSTEO
A14: Total Plan | C14: =SUM(C12:C13) -> 35132.9 | F14: Total Real | G14: =SUM(G12:G13) -> 35132.9
A15: Administrativos ( 5% - 10% - 15% ) | C15: =C14*0.05 -> 1756.645 | F15: Administrativos ( 5% - 10% - 15% ) | G15: =G14*0.05 -> 1756.645
A16: Total Plan | C16: =SUM(C14:C15) -> 36889.545 | F16: Total Real | G16: =SUM(G14:G15) -> 36889.545
A17: Insumos 30% | C17: =Insumos!C1 -> 14942 | F17: Insumos 30% | G17: =Insumos!C2 -> 14942
A18: Total Plan | C18: =SUM(C16:C17) -> 51831.545 | F18: Total Plan | G18: =SUM(G16:G17) -> 51831.545 | K18: 126000
A19: Financiamiento | C19: =C18*0.05 -> 2591.5773 | F19: Financiamiento | G19: =G18*0.05 -> 2591.5773 | K19: 4800 | L19: BONAICE 6 TEC
A20: Gasto plan Total | C20: =SUM(C18:C19) -> 54423.122 | F20: Gasto plan Total | G20: =SUM(G18:G19) -> 54423.122 | K20: =K18+K19 -> 130800 | L20: AUTORIZADO
A21: Utilidad Real | C21: =C10-C20 -> 76376.878 | F21: Utilidad Real | G21: =G10-G20 -> 76376.878
A22: Comisión Vendedor | C22: =C21*0.04 -> 3055.0751 | F22: Comisión Vendedor | G22: =G21*0.04 -> 3055.0751
A23: Utilidad Real | C23: =C21-C22 -> 73321.803 | F23: Utilidad Real | G23: =G21-G22 -> 73321.803
A25: Concepto | C25: Gasto plan | D25: Gasto real | E25: Diferencia | F25: Comentarios
A26: Nomina | C26: =Nomina!C1 -> 21000 | D26: =Nomina!C2 -> 21000 | E26: =C26-D26 -> 0
A27: Imss | C27: =Imss!C1 -> 1539 | D27: =Imss!C2 -> 1539 | E27: =C27-D27 -> 0
A28: Bonos | C28: =Bonos!C1 -> 4800 | D28: =Bonos!C2 -> 4800 | E28: =C28-D28 -> 0
A29: Gasolina | C29: =Gasolina!C1 -> 1500 | D29: =Gasolina!C2 -> 1500 | E29: =C29-D29 -> 0
A30: Desgaste de equipo | C30: ='Desgaste de Equipo'!B1 -> 2000 | D30: ='Desgaste de Equipo'!B2 -> 2000 | E30: =C30-D30 -> 0
A31: Administrativo | C31: =Administrativos!B1 -> 400 | D31: =Administrativos!B2 -> 400 | E31: =C31-D31 -> 0
A32: Insumos | E32: =C32-D32 -> 0
A33: Epp | C33: =Epp!B1 -> 350 | D33: =Epp!B2 -> 350 | E33: =C33-D33 -> 0
A34: Equipo | C34: ='Compra de Equipo'!B1 -> 350 | D34: ='Compra de Equipo'!B2 -> 350 | E34: =C34-D34 -> 0
A35: Total | C35: =SUM(C26:C34) -> 31939 | D35: =SUM(D26:D34) -> 31939 | E35: =SUM(E26:E32) -> 0
C37: DIFERENCIA | D37: =+D35-C35 -> 0
A39: COMENTARIO:

Sheet Nomina
A1: PRESUPUESTO | C1: 21000
A2: GASTO REAL | C2: =AJ14 -> 21000
A3: DIFERENCIA (+/-) | C3: =C1-C2 -> 0 | E3: ENERO
E4: JUE. | F4: VIE. | G4: SÁB. | H4: DOM. | I4: LUN. | J4: MAR. | K4: MIÉ. | L4: JUE. | M4: VIE. | N4: SÁB. | O4: DOM. | P4: LUN. | Q4: MAR. | R4: MIÉ. | S4: JUE. | T4: VIE. | U4: SÁB. | V4: DOM. | W4: LUN. | X4: MAR. | Y4: MIÉ. | Z4: JUE. | AA4: VIE. | AB4: SÁB. | AC4: DOM. | AD4: LUN. | AE4: MAR. | AF4: MIÉ. | AG4: JUE. | AH4: VIE. | AI4: SÁB.
A5: ITEM | B5: TRABAJADOR | C5: SALARIO SEMANAL | D5: SALARIO DIARIO | E5: 46023 | F5: 46024 | G5: 46025 | H5: 46026 | I5: 46027 | J5: 46028 | K5: 46029 | L5: 46030 | M5: 46031 | N5: 46032 | O5: 46033 | P5: 46034 | Q5: 46035 | R5: 46036 | S5: 46037 | T5: 46038 | U5: 46039 | V5: 46040 | W5: 46041 | X5: 46042 | Y5: 46043 | Z5: 46044 | AA5: 46045 | AB5: 46046 | AC5: 46047 | AD5: 46048 | AE5: 46049 | AF5: 46050 | AG5: 46051 | AH5: 46052 | AI5: 46053
A6: 1 | B6: TECNICO 1 | C6: 4900 | D6: =C6/7 -> 700 | E6: 700 | F6: 700 | G6: 700 | H6: 700 | I6: 700 | AJ6: =SUM(E6:AI6) -> 3500
A7: 2 | B7: TECNICO 2 | C7: 4900 | D7: =C7/7 -> 700 | E7: 700 | F7: 700 | G7: 700 | H7: 700 | I7: 700 | AJ7: =SUM(E7:AI7) -> 3500
A8: 3 | B8: TECNICO 3 | C8: 4900 | D8: =C8/7 -> 700 | E8: 700 | F8: 700 | G8: 700 | H8: 700 | I8: 700 | AJ8: =SUM(E8:AI8) -> 3500
A9: 4 | B9: TECNICO 4 | C9: 4900 | D9: =C9/7 -> 700 | E9: 700 | F9: 700 | G9: 700 | H9: 700 | I9: 700 | AJ9: =SUM(E9:AI9) -> 3500
A10: 5 | B10: TECNICO 5 | C10: 4900 | D10: =C10/7 -> 700 | E10: 700 | F10: 700 | G10: 700 | H10: 700 | I10: 700 | AJ10: =SUM(E10:AI10) -> 3500
A11: 6 | B11: TECNICO 6 | C11: 4900 | D11: =C11/7 -> 700 | E11: 700 | F11: 700 | G11: 700 | H11: 700 | I11: 700 | AJ11: =SUM(E11:AI11) -> 3500
A12: 7 | B12: TECNICO 7 | C12: 4900 | D12: =C12/7 -> 700 | AJ12: =SUM(E12:AI12) -> 0
A13: 8 | B13: TECNICO 8 | C13: 4900 | D13: =C13/7 -> 700 | AJ13: =SUM(E13:AI13) -> 0
AJ14: =SUM(AJ6:AJ13) -> 21000
D23: =34-9 -> 25

Sheet Equipo
A1: EQUIPO
A3: PRESUPUESTO | B3: 20000
A4: GASTO REAL | B4: =#REF! -> #REF!
A5: DIFERENCIA (+/-) | B5: =B3-B4 -> #REF!
C7: DIAS
A8: TRABAJADOR | B8: IMSS DIARIO | C8: 43959 | D8: 43960 | E8: 43961 | F8: 43962 | G8: 43963 | H8: 43964 | I8: 43965 | J8: 43966 | K8: 43967 | L8: 43968 | M8: 43969 | N8: 43970 | O8: 43971 | P8: 43972 | Q8: 43973 | R8: 43974 | S8: 43975 | T8: 43976 | U8: 43977 | V8: 43978 | W8: 43979 | X8: 43980 | Y8: 43981 | Z8: 43982 | AA8: 43983 | AB8: 43984 | AC8: 43985 | AD8: 43986 | AE8: 43987 | AF8: 43988 | AG8: 43989 | AH8: 43990 | AI8: 43991 | AJ8: 43992 | AK8: 43993 | AL8: 43994 | AM8: 43995 | AN8: 43996 | AO8: 43997
A9: MARCOS TOVAR | B9: 100 | C9: =B9 -> 100 | D9: =C9 -> 100 | E9: =D9 -> 100 | F9: =E9 -> 100 | G9: =F9 -> 100 | H9: =G9 -> 100 | I9: =H9 -> 100 | J9: =I9 -> 100 | ... AO9: =AN9 -> 100 | AP9: =SUM(B9:AO9) -> 4000
A10: LUIS MORENO | B10: 100 | C10: =B10 -> 100 | D10: =C10 -> 100 | E10: =D10 -> 100 | F10: =E10 -> 100 | G10: =F10 -> 100 | H10: =G10 -> 100 | I10: =H10 -> 100 | J10: =I10 -> 100 | ... AO10: =AN10 -> 100 | AP10: =SUM(B10:AO10) -> 4000
A11: ALFRDO | B11: 100 | C11: =B11 -> 100 | D11: =C11 -> 100 | E11: =D11 -> 100 | F11: =E11 -> 100 | G11: =F11 -> 100 | H11: =G11 -> 100 | I11: =H11 -> 100 | J11: =I11 -> 100 | ... AO11: =AN11 -> 100 | AP11: =SUM(B11:AO11) -> 4000
A12: ALAN CRUZ | B12: 100 | C12: =B12 -> 100 | D12: =C12 -> 100 | E12: =D12 -> 100 | F12: =E12 -> 100 | G12: =F12 -> 100 | H12: =G12 -> 100 | I12: =H12 -> 100 | J12: =I12 -> 100 | ... AO12: =AN12 -> 100 | AP12: =SUM(B12:AO12) -> 4000
AO13: TOTAL | AP13: =SUM(AP9:AP12) -> 16000

Sheet Imss
A1: PRESUPUESTO | C1: 1539
A2: GASTO REAL | C2: =AJ15 -> 1539
A3: DIFERENCIA (+/-) | C3: =C1-C2 -> 0
E4: ENERO
E5: JUE. | F5: VIE. | G5: SÁB. | H5: DOM. | I5: LUN. | J5: MAR. | K5: MIÉ. | L5: JUE. | M5: VIE. | N5: SÁB. | O5: DOM. | P5: LUN. | Q5: MAR. | R5: MIÉ. | S5: JUE. | T5: VIE. | U5: SÁB. | V5: DOM. | W5: LUN. | X5: MAR. | Y5: MIÉ. | Z5: JUE. | AA5: VIE. | AB5: SÁB. | AC5: DOM. | AD5: LUN. | AE5: MAR. | AF5: MIÉ. | AG5: JUE. | AH5: VIE. | AI5: SÁB.
A6: ITEM | B6: TRABAJADOR | C6: SALARIO SEMANAL | D6: IMSS DIARIO | E6: 46023 | F6: 46024 | G6: 46025 | H6: 46026 | I6: 46027 | J6: 46028 | K6: 46029 | L6: 46030 | M6: 46031 | N6: 46032 | O6: 46033 | P6: 46034 | Q6: 46035 | R6: 46036 | S6: 46037 | T6: 46038 | U6: 46039 | V6: 46040 | W6: 46041 | X6: 46042 | Y6: 46043 | Z6: 46044 | AA6: 46045 | AB6: 46046 | AC6: 46047 | AD6: 46048 | AE6: 46049 | AF6: 46050 | AG6: 46051 | AH6: 46052 | AI6: 46053
A7: 1 | B7: TECNICO 1 | C7: 4900 | D7: 51.3 | E7: 51.3 | F7: 51.3 | G7: 51.3 | H7: 51.3 | I7: 51.3 | AJ7: =SUM(E7:AI7) -> 256.5 | BN7: =SUM(E7:BM7) -> 513
A8: 2 | B8: TECNICO 2 | C8: 4900 | D8: 51.3 | E8: 51.3 | F8: 51.3 | G8: 51.3 | H8: 51.3 | I8: 51.3 | AJ8: =SUM(E8:AI8) -> 256.5 | BN8: =SUM(E8:BM8) -> 513
A9: 3 | B9: TECNICO 3 | C9: 4900 | D9: 51.3 | E9: 51.3 | F9: 51.3 | G9: 51.3 | H9: 51.3 | I9: 51.3 | AJ9: =SUM(E9:AI9) -> 256.5 | BN9: =SUM(E9:BM9) -> 513
A10: 4 | B10: TECNICO 4 | C10: 4900 | D10: 51.3 | E10: 51.3 | F10: 51.3 | G10: 51.3 | H10: 51.3 | I10: 51.3 | AJ10: =SUM(E10:AI10) -> 256.5 | BN10: =SUM(E10:BM10) -> 513
A11: 5 | B11: TECNICO 5 | C11: 4900 | D11: 51.3 | E11: 51.3 | F11: 51.3 | G11: 51.3 | H11: 51.3 | I11: 51.3 | AJ11: =SUM(E11:AI11) -> 256.5 | BN11: =SUM(E11:BM11) -> 513
A12: 6 | B12: TECNICO 6 | C12: 4900 | D12: 51.3 | E12: 51.3 | F12: 51.3 | G12: 51.3 | H12: 51.3 | I12: 51.3 | AJ12: =SUM(E12:AI12) -> 256.5 | BN12: =SUM(E12:BM12) -> 513
A13: 7 | B13: TECNICO 7 | C13: 4900 | D13: 51.3 | AJ13: =SUM(E13:AI13) -> 0
A14: 8 | B14: TECNICO 8 | C14: 4900 | D14: 51.3 | AJ14: =SUM(E14:AI14) -> 0 | BN14: =SUM(E14:BM14) -> 0
AJ15: =SUM(AJ7:AJ14) -> 1539 | BN15: =SUM(BN7:BN14) -> 3078

Sheet Insumos
A1: PRESUPUESTO | C1: =D35 -> 14942
A2: GASTO REAL | C2: =E35 -> 14942
A3: DIFERENCIA (+/-) | C3: =C1-C2 -> 0
A5: INSUMOS
A6: NO | B6: CONCEPTO | C6: UNIDADES | D6: COSTO PLAN | E6: COSTO REAL | F6: FECHA | G6: COMENTARIOS
A7: 1 | B7: CARTUCHOS DE SILICON DURETAN BASE DE POLIURETANO NEGRO | C7: 70 | D7: 10150 | E7: 10150
A8: 2 | B8: ROLLOS DE CINTA ADESHIVA MASKINGTAPE DE 3/4 X 20 MTRS DE LARGO | C8: 30 | D8: 2550 | E8: 2550
A9: 3 | B9: PACA DE TRAPO TIPO INDUSTRIAL DE 25 KILOS | C9: 1 | D9: 800 | E9: 800
A10: 4 | B10: COSTALES GRANDE PARA LA BASURA | C10: 8 | D10: 112 | E10: 112
A11: 5 | B11: GALONES DE TINHHER | C11: 2 | D11: 480 | E11: 480
A12: 6 | B12: PAQUETES DE REPUESTOS DE NAVAJA | C12: 2 | D12: 150 | E12: 150
A13: 7 | B13: PISTOLAS CALEFATEADORAS | C13: 4 | D13: 250 | E13: 250
A14: 8 | B14: CUBETAS VACIAS DE 19 LITROS | C14: 5 | D14: 100 | E14: 100
A15: 9 | B15: EXACTOS | C15: 5 | D15: 150 | E15: 150
A16: 10 | B16: ATOMIZADORES | C16: 5 | D16: 100 | E16: 100
A17: 11 | B17: JABON LIQUIDO | C17: 1 | D17: 100 | E17: 100
A18: 12
A19: 13
A20: 14
A21: 15
A22: 16
A23: 17
A24: 18
A25: 19
A26: 20
A27: 21
A28: 22
A29: 23
... A34: 28
D35: =SUM(D7:D34) -> 14942 | E35: =SUM(E7:E34) -> 14942
B38: 70 | C38: CARTUCHOS DE SILICON DURETAN BASE DE POLIURETANO NEGRO
B39: 30 | C39: ROLLOS DE CINTA ADESHIVA MASKINGTAPE DE 3/4 X 20 MTRS DE LARGO
B40: 1 | C40: PACA DE TRAPO TIPO INDUSTRIAL DE 25 KILOS
B41: 8 | C41: COSTALES GRANDE PARA LA BASURA
B42: 2 | C42: GALONES DE TINHHER
B43: 2 | C43: PAQUETES DE REPUESTOS DE NAVAJA
B44: 4 | C44: PISTOLAS CALEFATEADORAS
B45: 5 | C45: CUBETAS VACIAS DE 19 LITROS
B46: 5 | C46: EXACTOS
B47: 5 | C47: ATOMIZADORES
...

Sheet Bonos
A1: PRESUPUESTO | C1: 4800
A2: GASTO REAL | C2: =D29 -> 4800
A3: DIFERENCIA (+/-)
A5: BONOS
A6: NO | B6: CONCEPTO | C6: UNIDADES | D6: COSTO | E6: FECHA | F6: COMENTARIOS
A7: 1 | B7: TECNICO 1 | C7: 1 | D7: 800
A8: 2 | B8: TECNICO 2 | C8: 1 | D8: 800 | G8: 2000
A9: 3 | B9: TECNICO 3 | C9: 1 | D9: 800 | G9: 2000
A10: 4 | B10: TECNICO 4 | C10: 1 | D10: 800 | G10: 1000
A11: 5 | B11: TECNICO 5 | C11: 1 | D11: 800 | G11: 1500
A12: 6 | B12: TECNICO 6 | C12: 1 | D12: 800 | G12: 500
A13: 7 | G13: 500
A14: 8 | G14: 300
A15: 9 | G15: 1000
A16: 10
A17: 11
A18: 12
A19: 13
A20: 14
A21: 15
D29: =SUM(D7:D28) -> 4800

Sheet Gasolina
A1: PRESUPUESTO | C1: 1500
A2: GASTO REAL | C2: =C22 -> 1500
A3: DIFERENCIA (+/-)
A5: GASOLINA
A6: NO | B6: FECHA | C6: CANTIDAD | D6: RUTAS
A7: 1 | C7: 1500
A8: 2
A9: 3
A10: 4
A11: 5
A12: 6
A13: 7
A14: 8
A15: 9
A16: 10
A17: 11
A18: 12
A19: 13
... A21: 15
C22: =SUM(C7:C21) -> 1500

Sheet Administrativos
A1: PRESUPUESTO | B1: 400
A2: GASTO REAL | B2: =B14 -> 400
A3: DIFERENCIA (+/-) | B3: =B1-B2 -> 0
A5: GASTOS ADMINISTRATIVOS
A6: FECHA | B6: CANTIDAD
B7: 400
A14: TOTAL | B14: =SUM(B7:B13) -> 400

Sheet Desgaste de Equipo
A1: PRESUPUESTO | B1: 2000
A2: GASTO REAL | B2: =AH14 -> 2000
A3: DIFERENCIA (+/-) | B3: =B1-B2 -> 0
C5: ENERO
C6: JUE. | D6: VIE. | E6: SÁB. | F6: DOM. | G6: LUN. | H6: MAR. | I6: MIÉ. | J6: JUE. | K6: VIE. | L6: SÁB. | M6: DOM. | N6: LUN. | O6: MAR. | P6: MIÉ. | Q6: JUE. | R6: VIE. | S6: SÁB. | T6: DOM. | U6: LUN. | V6: MAR. | W6: MIÉ. | X6: JUE. | Y6: VIE. | Z6: SÁB. | AA6: DOM. | AB6: LUN. | AC6: MAR. | AD6: MIÉ. | AE6: JUE. | AF6: VIE. | AG6: SÁB.
A7: TRABAJADOR | B7: COSTO DIA | C7: 46023 | D7: 46024 | E7: 46025 | F7: 46026 | G7: 46027 | H7: 46028 | I7: 46029 | J7: 46030 | K7: 46031 | L7: 46032 | M7: 46033 | N7: 46034 | O7: 46035 | P7: 46036 | Q7: 46037 | R7: 46038 | S7: 46039 | T7: 46040 | U7: 46041 | V7: 46042 | W7: 46043 | X7: 46044 | Y7: 46045 | Z7: 46046 | AA7: 46047 | AB7: 46048 | AC7: 46049 | AD7: 46050 | AE7: 46051 | AF7: 46052 | AG7: 46053
A8: TECNICO 1 | B8: 100 | C8: 100 | D8: 100 | E8: 100 | F8: 100 | G8: 100 | AH8: =SUM(C8:AG8) -> 500
A9: TECNICO 2 | B9: 100 | C9: 100 | D9: 100 | E9: 100 | F9: 100 | G9: 100 | AH9: =SUM(C9:AG9) -> 500
A10: TECNICO 3 | B10: 100 | C10: 100 | D10: 100 | E10: 100 | F10: 100 | G10: 100 | AH10: =SUM(C10:AG10) -> 500
A11: TECNICO 4 | B11: 100 | C11: 100 | D11: 100 | E11: 100 | F11: 100 | G11: 100 | AH11: =SUM(C11:AG11) -> 500
A12: TECNICO 5 | B12: 100 | AH12: =SUM(C12:AG12) -> 0
A13: TECNICO 6 | B13: 100 | AH13: =SUM(C13:AG13) -> 0
AH14: =SUM(AH8:AH13) -> 2000

Sheet Epp
A1: PRESUPUESTO | B1: 350
A2: GASTO REAL | B2: =B14 -> 350
A3: DIFERENCIA (+/-) | B3: =B1-B2 -> 0
A5: GASTOS ADMINISTRATIVOS
A6: FECHA | B6: CANTIDAD
B7: 350
A14: TOTAL | B14: =SUM(B7:B13) -> 350
A16: NOTA:
A17: Cosideradolo siguiente:
A18: Lentes
A19: Playeras
A20: Pantalones
A21: Chaleco
A22: Zapatos
A23: Guante de trabajo

Sheet Compra de Equipo
A1: PRESUPUESTO | B1: 350
A2: GASTO REAL | B2: =B14 -> 350
A3: DIFERENCIA (+/-) | B3: =B1-B2 -> 0
A5: GASTOS ADMINISTRATIVOS
A6: FECHA | B6: CANTIDAD
B7: 350
A14: TOTAL | B14: =SUM(B7:B13) -> 350
A17: NOTA:
A18: Cosideradolo siguiente:
A19: Casco
A20: Mochila
A21: Arnes
A22: Mosqueton
A23: Silla
A24: Posa pie
A25: Rig
A26: Shunt
A27: Asensor
A28: Absorbica
... A30: Cuerdas

Sheet Tabla de montos 
A1: EPP
A2: MONTOS | B2: 25000 | C2: 50000 | D2: 75000 | E2: 100000 | F2: 150000 | G2: 200000 | H2: 300000 | I2: 400000 | J2: 5000000
A3: COSTO | B3: 1000 | C3: 2000 | D3: 3000 | E3: 5000 | F3: 6500 | G3: 8000 | H3: 100000 | I3: 12500 | J3: 14000
A5: COMPRA DE EQUIPOS
A6: MONTOS | B6: 25000 | C6: 50000 | D6: 75000 | E6: 100000 | F6: 150000 | G6: 200000 | H6: 300000 | I6: 400000 | J6: 5000000
A7: COSTO | B7: 1000 | C7: 2000 | D7: 3000 | E7: 5000 | F7: 6500 | G7: 8000 | H7: 100000 | I7: 12500 | J7: 14000
